2025-04-30 18:58:06 [32mINFO[0m [32mpytest tests/frontend/test_project_ui.py::test_create_project_manually_with_ui (setup)[0m
curl -X GET 'http://localhost:8111/authenticationTest.html?csrf' \
-H User-Agent:python-requests/2.32.3\
-H Accept-Encoding:gzip, deflate\
-H Accept:*/*\
-H Connection:keep-alive\
-H Authorization:Basic Ojg4MzI0Mzg1Mzk0ODg3NDcwNTc= \
-d ''
2025-04-30 18:58:17 [32mINFO[0m [32mpytest tests/frontend/test_project_ui.py::test_create_project_manually_with_ui (teardown)[0m
curl -X DELETE 'http://localhost:8111/app/rest/projects/id:yjPSqSXKMsm' \
-H User-Agent:python-requests/2.32.3\
-H Accept-Encoding:gzip, deflate\
-H Accept:application/json\
-H Connection:keep-alive\
-H Content-Type:application/json\
-H X-TC-CSRF-Token:a03dd4ec-7d86-4087-a264-1efc3ada860e\
-H Cookie:TCSESSIONID=F35371BFAF6F55094DE36F3A0132CEFB\
-H Content-Length:0\
-H Authorization:Basic Ojg4MzI0Mzg1Mzk0ODg3NDcwNTc= \
-d '' 

2025-04-30 18:58:17 [32mINFO[0m 	RESPOSE:
STATUS_CODE: [31m404[0m
DATA: [31m{"errors":[{"message":"Responding with error, status code: 404 (Not Found).\nDetails: jetbrains.buildServer.server.rest.errors.NotFoundException: No project found by locator 'count:1,id:yjPSqSXKMsm'. Project cannot be found by external id 'yjPSqSXKMsm'.\nCould not find the entity requested. Check the reference is correct and the user has permissions to access the entity."}]}[0m